<?xml version="1.0"?>
<robot name="cart_pole">

  <!-- Definizione del carrello -->
  <link name="carrello">
    <inertial>
      <origin xyz="0 0 0" rpy="0 0 0"/>
      <mass value="1.0"/>
      <inertia ixx="0.1" ixy="0.0" ixz="0.0" iyy="0.1" iyz="0.0" izz="0.1"/>
    </inertial>
    <visual>
      <origin xyz="0 0 0.1" rpy="0 0 0"/>
      <geometry>
        <box size="0.5 0.2 0.2"/>
      </geometry>
      <material name="blue">
        <color rgba="0 0 1 1"/>
      </material>
    </visual>
    <collision>
      <origin xyz="0 0 0.1" rpy="0 0 0"/>
      <geometry>
        <box size="0.5 0.2 0.2"/>
      </geometry>
    </collision>
  </link>

  <!-- Definizione del palo -->
  <link name="palo">
    <inertial>
      <origin xyz="0 0 0.5" rpy="0 0 0"/>
      <mass value="0.5"/>
      <inertia ixx="0.02" ixy="0.0" ixz="0.0" iyy="0.02" iyz="0.0" izz="0.02"/>
    </inertial>
    <visual>
      <origin xyz="0 0 0.5" rpy="0 0 0"/>
      <geometry>
        <cylinder length="1.0" radius="0.05"/>
      </geometry>
      <material name="red">
        <color rgba="1 0 0 1"/>
      </material>
    </visual>
    <collision>
      <origin xyz="0 0 0.5" rpy="0 0 0"/>
      <geometry>
        <cylinder length="1.0" radius="0.05"/>
      </geometry>
    </collision>
  </link>

  <!-- Giunto rotazionale tra il carrello e il palo -->
  <joint name="joint_cart_pole" type="revolute">
    <parent link="carrello"/>
    <child link="palo"/>
    <origin xyz="0 0 0.1" rpy="0 0 0"/>
    <axis xyz="0 1 0"/>
    <limit lower="-3.14" upper="3.14" effort="100.0" velocity="10.0"/>
  </joint>

  <!-- Giunto prismatico per il movimento del carrello -->
  <joint name="joint_cart_rail" type="prismatic">
    <parent link="world"/>
    <child link="carrello"/>
    <origin xyz="0 0 0" rpy="0 0 0"/>
    <axis xyz="1 0 0"/>
    <limit lower="-5.0" upper="5.0" effort="100.0" velocity="1.0"/>
  </joint>

</robot>
